Workbook
Name CurvaX: '_DATOS'!$A$3:$A$6
Name CurvaY: '_DATOS'!$B$3:$B$6
Name AjusteX: '_DATOS'!$H$3:$H$203
Name AjusteY: '_DATOS'!$I$3:$I$203
Name MDSX: '_DATOS'!$K$3
Name MDSY: '_DATOS'!$L$3

Sheet Reporte
C1: GOBIERNO REGIONAL CUSCO
C2: Gerencia Regional de Transportes y Comunicaciones Cusco
C3: SUB GERENCIA DE COBERTURA Y COMUNICACIONES
C4: UNIDAD FUNCIONAL ESTUDIOS Y PROYECTOS
C5: Laboratorio de Mecánica de Suelos, Materiales y Pavimentos
C6: «Año de la recuperación y consolidación de la economía peruana»
A8: CÓDIGO
A10: PROYECTO
A11: UBICACIÓN | B11: Lugar: | D11: Distrito: | F11: Provincia: | H11: Dpto:
A12: SOLICITANTE | E12: Fecha Muestreo:
A13: COORDENADAS | B13: E: | E13: N: | H13: Prof. (m):
A14: DATOS DE MUESTRA | B14: Explor.: | D14: Progresiva: | F14: Estrato: | H14: Lado:
A16: COMPACTACIÓN PROCTOR MODIFICADO - MTC E 115
A17: EQUIPO / MOLDE | B17: Código: | D17: Diám. (cm): | F17: Altura (cm): | H17: Vol. (cm³): | I17: =IF(AND(N(E17)>0,N(G17)>0),ROUND(PI()*POWER(E17,2)*G17/4,1),"")
A18: COMPACTACIÓN | B18: Golpes/capa: | D18: N° capas: | F18: Martillo (lb):
A20: DATOS DE ENSAYO
A21: Parámetro | B21: M1 | D21: M2 | F21: M3 | H21: M4
A22: Masa del molde (g)
A23: Masa molde + suelo húmedo (g)
A24: Agua incrementada (g)
A25: Masa del suelo húmedo (g) | B25: =IF(COUNT(B22:B23)=2,B23-B22,"") | D25: =IF(COUNT(D22:D23)=2,D23-D22,"") | F25: =IF(COUNT(F22:F23)=2,F23-F22,"") | H25: =IF(COUNT(H22:H23)=2,H23-H22,"")
A26: Volumen del molde (cm³) | B26: =IF(N($I$17)>0,$I$17,2124) | D26: =IF(N($I$17)>0,$I$17,2124) | F26: =IF(N($I$17)>0,$I$17,2124) | H26: =IF(N($I$17)>0,$I$17,2124)
A27: Densidad húmeda (g/cm³) | B27: =IF(AND(ISNUMBER(B25),N(B26)>0),IFERROR(B25/B26,0),"") | D27: =IF(AND(ISNUMBER(D25),N(D26)>0),IFERROR(D25/D26,0),"") | F27: =IF(AND(ISNUMBER(F25),N(F26)>0),IFERROR(F25/F26,0),"") | H27: =IF(AND(ISNUMBER(H25),N(H26)>0),IFERROR(H25/H26,0),"")
A30: CÁLCULO DE LA HUMEDAD
A31: Parámetro | B31: M1 | D31: M2 | F31: M3 | H31: M4
A32: Cápsula N°
A33: Masa de cápsula (g)
A34: Masa cápsula + suelo húmedo (g)
A35: Masa cápsula + suelo seco (g)
A36: Masa de agua (g) | B36: =IF(COUNT(B34:B35)=2,B34-B35,"") | D36: =IF(COUNT(D34:D35)=2,D34-D35,"") | F36: =IF(COUNT(F34:F35)=2,F34-F35,"") | H36: =IF(COUNT(H34:H35)=2,H34-H35,"")
A37: Masa de suelo seco (g) | B37: =IF(COUNT(B33,B35)=2,B35-B33,"") | D37: =IF(COUNT(D33,D35)=2,D35-D33,"") | F37: =IF(COUNT(F33,F35)=2,F35-F33,"") | H37: =IF(COUNT(H33,H35)=2,H35-H33,"")
A38: Contenido de humedad (%) | B38: =IF(AND(ISNUMBER(B37),N(B37)>0),IFERROR(B36/B37*100,0),"") | D38: =IF(AND(ISNUMBER(D37),N(D37)>0),IFERROR(D36/D37*100,0),"") | F38: =IF(AND(ISNUMBER(F37),N(F37)>0),IFERROR(F36/F37*100,0),"") | H38: =IF(AND(ISNUMBER(H37),N(H37)>0),IFERROR(H36/H37*100,0),"")
A39: Densidad seca (g/cm³) | B39: =IF(AND(ISNUMBER(B38),ISNUMBER(B27)),IFERROR(B27/(1+B38/100),0),"") | D39: =IF(AND(ISNUMBER(D38),ISNUMBER(D27)),IFERROR(D27/(1+D38/100),0),"") | F39: =IF(AND(ISNUMBER(F38),ISNUMBER(F27)),IFERROR(F27/(1+F38/100),0),"") | H39: =IF(AND(ISNUMBER(H38),ISNUMBER(H27)),IFERROR(H27/(1+H38/100),0),"")
A41: MÁXIMA DENSIDAD SECA (g/cm³) | B41: =IF(ISNUMBER(_DATOS!$F$5),_DATOS!$F$5,"")
A42: HUMEDAD ÓPTIMA (%) | B42: =IF(ISNUMBER(_DATOS!$F$4),_DATOS!$F$4,"")
A45: CURVA DE COMPACTACIÓN
A77: ESP. ENSAYOS GEOTECNICOS | D77: ESP. SUELOS Y PAVIMENTOS | G77: SUPERVISOR

Sheet _DATOS
F1: =IFERROR(INDEX(LINEST(B3:B6,A3:A6^{1,2,3}),1,1),"") | G1: =IFERROR(INDEX(LINEST(B3:B6,A3:A6^{1,2,3}),1,4),"")
F2: =IFERROR(INDEX(LINEST(B3:B6,A3:A6^{1,2,3}),1,2),"") | G2: =IF(COUNT(A3:A6)<4,NA(),MIN(A3:A6)-0.05*(MAX(A3:A6)-MIN(A3:A6)))
A3: =IF(OR(NOT(ISNUMBER(Reporte!B38)),NOT(ISNUMBER(Reporte!B39)),Reporte!B39=0),NA(),Reporte!B38) | B3: =IF(ISNA(A3),NA(),Reporte!B39) | F3: =IFERROR(INDEX(LINEST(B3:B6,A3:A6^{1,2,3}),1,3),"") | G3: =IF(NOT(ISNUMBER(G2)),NA(),((MAX(A3:A6)+0.05*(MAX(A3:A6)-MIN(A3:A6)))-G2)/200) | H3: =IF(OR(COUNT($A$3:$A$6)<4,NOT(ISNUMBER($G$2))),"",$G$2+(ROW()-3)*$G$3) | I3: =IF(H3="","",$F$1*H3^3+$F$2*H3^2+$F$3*H3+$G$1) | K3: =IF(ISNUMBER($F$4),$F$4,NA()) | L3: =IF(ISNUMBER($F$5),$F$5,NA())
A4: =IF(OR(NOT(ISNUMBER(Reporte!D38)),NOT(ISNUMBER(Reporte!D39)),Reporte!D39=0),NA(),Reporte!D38) | B4: =IF(ISNA(A4),NA(),Reporte!D39) | F4: =IF(COUNT($A$3:$A$6)>=4,IFERROR(INDEX($H$3:$H$203,MATCH(MAX($I$3:$I$203),$I$3:$I$203,0)),""),IF(ISNUMBER($F$11),$F$11,"")) | H4: =IF(OR(COUNT($A$3:$A$6)<4,NOT(ISNUMBER($G$2))),"",$G$2+(ROW()-3)*$G$3) | I4: =IF(H4="","",$F$1*H4^3+$F$2*H4^2+$F$3*H4+$G$1)
A5: =IF(OR(NOT(ISNUMBER(Reporte!F38)),NOT(ISNUMBER(Reporte!F39)),Reporte!F39=0),NA(),Reporte!F38) | B5: =IF(ISNA(A5),NA(),Reporte!F39) | F5: =IF(COUNT($A$3:$A$6)>=4,IFERROR(MAX($I$3:$I$203),""),IF(ISNUMBER($F$12),$F$12,"")) | H5: =IF(OR(COUNT($A$3:$A$6)<4,NOT(ISNUMBER($G$2))),"",$G$2+(ROW()-3)*$G$3) | I5: =IF(H5="","",$F$1*H5^3+$F$2*H5^2+$F$3*H5+$G$1)
A6: =IF(OR(NOT(ISNUMBER(Reporte!H38)),NOT(ISNUMBER(Reporte!H39)),Reporte!H39=0),NA(),Reporte!H38) | B6: =IF(ISNA(A6),NA(),Reporte!H39) | H6: =IF(OR(COUNT($A$3:$A$6)<4,NOT(ISNUMBER($G$2))),"",$G$2+(ROW()-3)*$G$3) | I6: =IF(H6="","",$F$1*H6^3+$F$2*H6^2+$F$3*H6+$G$1)
H7: =IF(OR(COUNT($A$3:$A$6)<4,NOT(ISNUMBER($G$2))),"",$G$2+(ROW()-3)*$G$3) | I7: =IF(H7="","",$F$1*H7^3+$F$2*H7^2+$F$3*H7+$G$1)
F8: =IFERROR(INDEX(LINEST(B3:B6,A3:A6^{1,2}),1,1),"") | H8: =IF(OR(COUNT($A$3:$A$6)<4,NOT(ISNUMBER($G$2))),"",$G$2+(ROW()-3)*$G$3) | I8: =IF(H8="","",$F$1*H8^3+$F$2*H8^2+$F$3*H8+$G$1)
F9: =IFERROR(INDEX(LINEST(B3:B6,A3:A6^{1,2}),1,2),"") | H9: =IF(OR(COUNT($A$3:$A$6)<4,NOT(ISNUMBER($G$2))),"",$G$2+(ROW()-3)*$G$3) | I9: =IF(H9="","",$F$1*H9^3+$F$2*H9^2+$F$3*H9+$G$1)
F10: =IFERROR(INDEX(LINEST(B3:B6,A3:A6^{1,2}),1,3),"") | H10: =IF(OR(COUNT($A$3:$A$6)<4,NOT(ISNUMBER($G$2))),"",$G$2+(ROW()-3)*$G$3) | I10: =IF(H10="","",$F$1*H10^3+$F$2*H10^2+$F$3*H10+$G$1)
F11: =IF(AND(ISNUMBER(F8),N(F8)<>0),-F9/(2*F8),"") | H11: =IF(OR(COUNT($A$3:$A$6)<4,NOT(ISNUMBER($G$2))),"",$G$2+(ROW()-3)*$G$3) | I11: =IF(H11="","",$F$1*H11^3+$F$2*H11^2+$F$3*H11+$G$1)
F12: =IF(ISNUMBER(F11),F8*F11^2+F9*F11+F10,"") | H12: =IF(OR(COUNT($A$3:$A$6)<4,NOT(ISNUMBER($G$2))),"",$G$2+(ROW()-3)*$G$3) | I12: =IF(H12="","",$F$1*H12^3+$F$2*H12^2+$F$3*H12+$G$1)
H13: =IF(OR(COUNT($A$3:$A$6)<4,NOT(ISNUMBER($G$2))),"",$G$2+(ROW()-3)*$G$3) | I13: =IF(H13="","",$F$1*H13^3+$F$2*H13^2+$F$3*H13+$G$1)
H14: =IF(OR(COUNT($A$3:$A$6)<4,NOT(ISNUMBER($G$2))),"",$G$2+(ROW()-3)*$G$3) | I14: =IF(H14="","",$F$1*H14^3+$F$2*H14^2+$F$3*H14+$G$1)
H15: =IF(OR(COUNT($A$3:$A$6)<4,NOT(ISNUMBER($G$2))),"",$G$2+(ROW()-3)*$G$3) | I15: =IF(H15="","",$F$1*H15^3+$F$2*H15^2+$F$3*H15+$G$1)
H16: =IF(OR(COUNT($A$3:$A$6)<4,NOT(ISNUMBER($G$2))),"",$G$2+(ROW()-3)*$G$3) | I16: =IF(H16="","",$F$1*H16^3+$F$2*H16^2+$F$3*H16+$G$1)
H17: =IF(OR(COUNT($A$3:$A$6)<4,NOT(ISNUMBER($G$2))),"",$G$2+(ROW()-3)*$G$3) | I17: =IF(H17="","",$F$1*H17^3+$F$2*H17^2+$F$3*H17+$G$1)
H18: =IF(OR(COUNT($A$3:$A$6)<4,NOT(ISNUMBER($G$2))),"",$G$2+(ROW()-3)*$G$3) | I18: =IF(H18="","",$F$1*H18^3+$F$2*H18^2+$F$3*H18+$G$1)
H19: =IF(OR(COUNT($A$3:$A$6)<4,NOT(ISNUMBER($G$2))),"",$G$2+(ROW()-3)*$G$3) | I19: =IF(H19="","",$F$1*H19^3+$F$2*H19^2+$F$3*H19+$G$1)
H20: =IF(OR(COUNT($A$3:$A$6)<4,NOT(ISNUMBER($G$2))),"",$G$2+(ROW()-3)*$G$3) | I20: =IF(H20="","",$F$1*H20^3+$F$2*H20^2+$F$3*H20+$G$1)
H21: =IF(OR(COUNT($A$3:$A$6)<4,NOT(ISNUMBER($G$2))),"",$G$2+(ROW()-3)*$G$3) | I21: =IF(H21="","",$F$1*H21^3+$F$2*H21^2+$F$3*H21+$G$1)
H22: =IF(OR(COUNT($A$3:$A$6)<4,NOT(ISNUMBER($G$2))),"",$G$2+(ROW()-3)*$G$3) | I22: =IF(H22="","",$F$1*H22^3+$F$2*H22^2+$F$3*H22+$G$1)
H23: =IF(OR(COUNT($A$3:$A$6)<4,NOT(ISNUMBER($G$2))),"",$G$2+(ROW()-3)*$G$3) | I23: =IF(H23="","",$F$1*H23^3+$F$2*H23^2+$F$3*H23+$G$1)
H24: =IF(OR(COUNT($A$3:$A$6)<4,NOT(ISNUMBER($G$2))),"",$G$2+(ROW()-3)*$G$3) | I24: =IF(H24="","",$F$1*H24^3+$F$2*H24^2+$F$3*H24+$G$1)
... H203: =IF(OR(COUNT($A$3:$A$6)<4,NOT(ISNUMBER($G$2))),"",$G$2+(ROW()-3)*$G$3) | I203: =IF(H203="","",$F$1*H203^3+$F$2*H203^2+$F$3*H203+$G$1)

Sheet _GRAFICOS
A1: id | B1: titulo | C1: tipo | D1: ancla | E1: ancho_px | F1: alto_px | G1: x_log | H1: x_min | I1: x_max | J1: y_min | K1: y_max | L1: titulo_x | M1: titulo_y | N1: serie | O1: estilo | P1: rango_x | Q1: rango_y | R1: color | S1: orden
A2: curva_compactacion | B2: Curva de Compactación Proctor Modificado | C2: xy | D2: A46 | E2: 620 | F2: 480 | G2: NO | L2: Contenido de Humedad (%) | M2: Densidad Seca (g/cm³) | N2: Ajuste MTC (Cúbico) | O2: linea_suave | P2: '_DATOS'!$H$3:$H$203 | Q2: '_DATOS'!$I$3:$I$203 | R2: DC2626 | S2: 1
A3: curva_compactacion | N3: Puntos de Ensayo | O3: marcador | P3: '_DATOS'!$A$3:$A$6 | Q3: '_DATOS'!$B$3:$B$6 | R3: 1E40AF | S3: 2
A4: curva_compactacion | N4: Máxima Densidad Seca | O4: marcador | P4: '_DATOS'!$K$3:$K$3 | Q4: '_DATOS'!$L$3:$L$3 | R4: 059669 | S4: 3

Sheet _MAPA
A1: ruta | B1: celda | C1: tipo | D1: formato
A2: meta.codigo_ensayo | B2: B8 | C2: texto
A3: meta.proyecto_nombre | B3: B10 | C3: texto
A4: meta.tramo_nombre | B4: C11 | C4: texto
A5: meta.distrito | B5: E11 | C5: texto
A6: meta.provincia | B6: G11 | C6: texto
A7: meta.departamento | B7: I11 | C7: texto
A8: meta.solicitante | B8: B12 | C8: texto
A9: meta.fecha_muestreo | B9: G12 | C9: fecha | D9: dddd d" de "mmmm" de "yyyy
A10: meta.coordenada_este | B10: C13 | C10: numero | D10: 0.00
A11: meta.coordenada_norte | B11: F13 | C11: numero | D11: 0.00
A12: meta.profundidad | B12: I13 | C12: texto
A13: meta.calicata | B13: C14 | C13: texto
A14: meta.progresiva | B14: E14 | C14: texto
A15: meta.estrato | B15: G14 | C15: texto
A16: meta.lado | B16: I14 | C16: texto
A17: datos.general_fields.codigo_molde | B17: C17 | C17: texto
A18: datos.general_fields.diametro_cm | B18: E17 | C18: numero | D18: 0.00
A19: datos.general_fields.altura_cm | B19: G17 | C19: numero | D19: 0.00
A20: datos.general_fields.golpes_por_capa | B20: C18 | C20: numero | D20: 0
A21: datos.general_fields.numero_capas | B21: E18 | C21: numero | D21: 0
A22: datos.general_fields.masa_martillo_lb | B22: G18 | C22: numero | D22: 0
A23: datos.tables.datos_ensayo.m1.masa_molde | B23: B22 | C23: numero | D23: 0.00
A24: datos.tables.datos_ensayo.m1.masa_suelo_humedo_molde | B24: B23 | C24: numero | D24: 0.00
A25: datos.tables.datos_ensayo.m1.agua_incrementada | B25: B24 | C25: numero | D25: 0.00
A26: datos.tables.datos_ensayo.m2.masa_molde | B26: D22 | C26: numero | D26: 0.00
A27: datos.tables.datos_ensayo.m2.masa_suelo_humedo_molde | B27: D23 | C27: numero | D27: 0.00
A28: datos.tables.datos_ensayo.m2.agua_incrementada | B28: D24 | C28: numero | D28: 0.00
A29: datos.tables.datos_ensayo.m3.masa_molde | B29: F22 | C29: numero | D29: 0.00
... A34: datos.tables.datos_ensayo.m4.agua_incrementada | B34: H24 | C34: numero | D34: 0.00
A35: datos.tables.calculo_humedad.m1.capsula_nro | B35: B32 | C35: texto
A36: datos.tables.calculo_humedad.m1.masa_capsula | B36: B33 | C36: numero | D36: 0.00
A37: datos.tables.calculo_humedad.m1.masa_capsula_suelo_humedo | B37: B34 | C37: numero | D37: 0.00
A38: datos.tables.calculo_humedad.m1.masa_capsula_suelo_seco | B38: B35 | C38: numero | D38: 0.00
A39: datos.tables.calculo_humedad.m2.capsula_nro | B39: D32 | C39: texto
A40: datos.tables.calculo_humedad.m2.masa_capsula | B40: D33 | C40: numero | D40: 0.00
A41: datos.tables.calculo_humedad.m2.masa_capsula_suelo_humedo | B41: D34 | C41: numero | D41: 0.00
A42: datos.tables.calculo_humedad.m2.masa_capsula_suelo_seco | B42: D35 | C42: numero | D42: 0.00
A43: datos.tables.calculo_humedad.m3.capsula_nro | B43: F32 | C43: texto
A44: datos.tables.calculo_humedad.m3.masa_capsula | B44: F33 | C44: numero | D44: 0.00
...
