Workbook
Name FluidezGolpesX: '_DATOS'!$A$3:$A$5
Name FluidezHumedadY: '_DATOS'!$B$3:$B$5
Name FluidezLogX: '_DATOS'!$C$3:$C$5
Name RegresionX: '_DATOS'!$D$3:$D$9
Name RegresionY: '_DATOS'!$E$3:$E$9
Name PuntoLLX: '_DATOS'!$H$3
Name PuntoLLY: '_DATOS'!$I$3
Name CartaLLX: '_DATOS'!$F$4
Name CartaIPY: '_DATOS'!$F$6
Name LineaAX: '_DATOS'!$H$5:$H$6
Name LineaAY: '_DATOS'!$I$5:$I$6

Sheet Reporte
C1: GOBIERNO REGIONAL CUSCO
C2: Gerencia Regional de Transportes y Comunicaciones Cusco
C3: SUB GERENCIA DE COBERTURA Y COMUNICACIONES
C4: UNIDAD FUNCIONAL ESTUDIOS Y PROYECTOS
C5: Laboratorio de Mecánica de Suelos, Materiales y Pavimentos
C6: «Año de la recuperación y consolidación de la economía peruana»
A8: CÓDIGO
A10: PROYECTO
A11: UBICACIÓN | B11: Lugar: | D11: Distrito: | F11: Provincia: | H11: Dpto:
A12: SOLICITANTE | E12: Fecha Muestreo:
A13: COORDENADAS | B13: E: | E13: N: | H13: Prof. (m):
A14: DATOS DE MUESTRA | B14: Explor.: | D14: Progresiva: | F14: Estrato: | H14: Lado:
A16: DETERMINACIÓN DEL LÍMITE LÍQUIDO - MTC E 110
A17: Parámetro | B17: 1 | C17: 2 | D17: 3
A18: Cod. Recipiente
A19: N° de Golpes
A20: Peso del recipiente (g)
A21: Recip. + suelo húmedo (g)
A22: Recip. + suelo seco (g)
A23: Peso agua (g) | B23: =IF(COUNT(B21:B22)=2,B21-B22,"") | C23: =IF(COUNT(C21:C22)=2,C21-C22,"") | D23: =IF(COUNT(D21:D22)=2,D21-D22,"")
A24: Peso suelo seco (g) | B24: =IF(COUNT(B20,B22)=2,B22-B20,"") | C24: =IF(COUNT(C20,C22)=2,C22-C20,"") | D24: =IF(COUNT(D20,D22)=2,D22-D20,"")
A25: % de Humedad | B25: =IF(AND(ISNUMBER(B24),N(B24)>0),IFERROR(B23/B24*100,0),"") | C25: =IF(AND(ISNUMBER(C24),N(C24)>0),IFERROR(C23/C24*100,0),"") | D25: =IF(AND(ISNUMBER(D24),N(D24)>0),IFERROR(D23/D24*100,0),"")
A26: LL Corregido (%) | B26: =IF(AND(ISNUMBER(B25),N(B19)>0),B25*POWER(B19/25,0.121),"") | C26: =IF(AND(ISNUMBER(C25),N(C19)>0),C25*POWER(C19/25,0.121),"") | D26: =IF(AND(ISNUMBER(D25),N(D19)>0),D25*POWER(D19/25,0.121),"")
A27: LÍMITE LÍQUIDO (L.L.) | B27: =IF(COUNTIF(B19:D19,25)>0,INDEX(B25:D25,MATCH(25,B19:D19,0)),IF(COUNT(B26:D26)>0,AVERAGE(B26:D26),0))
A29: DETERMINACIÓN DEL LÍMITE PLÁSTICO - MTC E 111
A30: Parámetro | B30: 1 | C30: 2
A31: Cod. Recipiente
A32: Peso del recipiente (g)
A33: Recip. + suelo húmedo (g)
A34: Recip. + suelo seco (g)
A35: Peso agua (g) | B35: =IF(COUNT(B33:B34)=2,B33-B34,"") | C35: =IF(COUNT(C33:C34)=2,C33-C34,"")
A36: Peso suelo seco (g) | B36: =IF(COUNT(B32,B34)=2,B34-B32,"") | C36: =IF(COUNT(C32,C34)=2,C34-C32,"")
A37: % de Humedad | B37: =IF(AND(ISNUMBER(B36),N(B36)>0),IFERROR(B35/B36*100,0),"") | C37: =IF(AND(ISNUMBER(C36),N(C36)>0),IFERROR(C35/C36*100,0),"")
A38: LÍMITE PLÁSTICO (L.P.) | B38: =IF(COUNT(B37:C37)>0,AVERAGE(B37:C37),0)
A39: ÍNDICE DE PLASTICIDAD (I.P.) | B39: =IF(AND(ISNUMBER(B27),ISNUMBER(B38)),B27-B38,"")
A40: IP | C40: Descripción
A41: 0 - 3 | C41: No plástico
A42: 3 - 15 | C42: Ligeramente plástico
A43: 15 - 30 | C43: Baja plasticidad
A44: > 30 | C44: Alta plasticidad
...

Sheet _DATOS
F1: =IFERROR(SLOPE(B3:B5,C3:C5),0)
F2: =IFERROR(INTERCEPT(B3:B5,C3:C5),0)
A3: =IF(OR(Reporte!B19="",N(Reporte!B19)=0),NA(),Reporte!B19) | B3: =IF(ISNA(A3),NA(),Reporte!B25) | C3: =IF(ISNA(A3),NA(),LOG10(A3)) | D3: 10 | E3: =$F$1*LOG10(D3)+$F$2 | F3: =F1*LOG10(25)+F2 | H3: 25 | I3: =F3
A4: =IF(OR(Reporte!C19="",N(Reporte!C19)=0),NA(),Reporte!C19) | B4: =IF(ISNA(A4),NA(),Reporte!C25) | C4: =IF(ISNA(A4),NA(),LOG10(A4)) | D4: 12.5 | E4: =$F$1*LOG10(D4)+$F$2 | F4: =Reporte!B27
A5: =IF(OR(Reporte!D19="",N(Reporte!D19)=0),NA(),Reporte!D19) | B5: =IF(ISNA(A5),NA(),Reporte!D25) | C5: =IF(ISNA(A5),NA(),LOG10(A5)) | D5: 15 | E5: =$F$1*LOG10(D5)+$F$2 | F5: =Reporte!B38 | H5: 20 | I5: 0
D6: 20 | E6: =$F$1*LOG10(D6)+$F$2 | F6: =F4-F5 | H6: 100 | I6: 58.4
D7: 25 | E7: =$F$1*LOG10(D7)+$F$2
D8: 35 | E8: =$F$1*LOG10(D8)+$F$2
D9: 50 | E9: =$F$1*LOG10(D9)+$F$2

Sheet _GRAFICOS
A1: id | B1: titulo | C1: tipo | D1: ancla | E1: ancho_px | F1: alto_px | G1: x_log | H1: x_min | I1: x_max | J1: y_min | K1: y_max | L1: titulo_x | M1: titulo_y | N1: serie | O1: estilo | P1: rango_x | Q1: rango_y | R1: color | S1: orden
A2: curva_fluidez | B2: Determinación del Límite Líquido (Curva de Fluidez) | C2: xy | D2: A58 | E2: 455 | F2: 425 | G2: SI | H2: 10 | I2: 50 | L2: Número de Golpes | M2: % de Humedad | N2: Línea de Fluidez (Regresión) | O2: linea | P2: '_DATOS'!$D$3:$D$9 | Q2: '_DATOS'!$E$3:$E$9 | R2: DC2626 | S2: 1
A3: curva_fluidez | N3: Puntos de Ensayo | O3: marcador | P3: '_DATOS'!$A$3:$A$5 | Q3: '_DATOS'!$B$3:$B$5 | R3: 1E40AF | S3: 2
A4: curva_fluidez | N4: L.L. (25 golpes) | O4: marcador | P4: '_DATOS'!$H$3:$H$3 | Q4: '_DATOS'!$I$3:$I$3 | R4: 059669 | S4: 3
A5: carta_plasticidad | B5: Carta de Plasticidad de Casagrande | C5: xy | D5: F58 | E5: 315 | F5: 425 | G5: NO | H5: 0 | I5: 100 | J5: 0 | K5: 60 | L5: Límite Líquido (LL) | M5: Índice de Plasticidad (IP) | N5: Línea A | O5: linea | P5: '_DATOS'!$H$5:$H$6 | Q5: '_DATOS'!$I$5:$I$6 | R5: 475569 | S5: 1
A6: carta_plasticidad | N6: Muestra | O6: marcador | P6: '_DATOS'!$F$4:$F$4 | Q6: '_DATOS'!$F$6:$F$6 | R6: 7C3AED | S6: 2

Sheet _MAPA
A1: ruta | B1: celda | C1: tipo | D1: formato
A2: meta.codigo_ensayo | B2: B8 | C2: texto
A3: meta.proyecto_nombre | B3: B10 | C3: texto
A4: meta.tramo_nombre | B4: C11 | C4: texto
A5: meta.distrito | B5: E11 | C5: texto
A6: meta.provincia | B6: G11 | C6: texto
A7: meta.departamento | B7: I11 | C7: texto
A8: meta.solicitante | B8: B12 | C8: texto
A9: meta.fecha_muestreo | B9: G12 | C9: fecha | D9: dddd d" de "mmmm" de "yyyy
A10: meta.coordenada_este | B10: C13 | C10: numero | D10: 0.00
A11: meta.coordenada_norte | B11: F13 | C11: numero | D11: 0.00
A12: meta.profundidad | B12: I13 | C12: texto
A13: meta.calicata | B13: C14 | C13: texto
A14: meta.progresiva | B14: E14 | C14: texto
A15: meta.estrato | B15: G14 | C15: texto
A16: meta.lado | B16: I14 | C16: texto
A17: datos.tables.limite_liquido.1.codigo | B17: B18 | C17: texto
A18: datos.tables.limite_liquido.1.golpes | B18: B19 | C18: numero | D18: 0
A19: datos.tables.limite_liquido.1.tara | B19: B20 | C19: numero | D19: 0.00
A20: datos.tables.limite_liquido.1.humedo | B20: B21 | C20: numero | D20: 0.00
A21: datos.tables.limite_liquido.1.seco | B21: B22 | C21: numero | D21: 0.00
A22: datos.tables.limite_liquido.2.codigo | B22: C18 | C22: texto
A23: datos.tables.limite_liquido.2.golpes | B23: C19 | C23: numero | D23: 0
A24: datos.tables.limite_liquido.2.tara | B24: C20 | C24: numero | D24: 0.00
A25: datos.tables.limite_liquido.2.humedo | B25: C21 | C25: numero | D25: 0.00
A26: datos.tables.limite_liquido.2.seco | B26: C22 | C26: numero | D26: 0.00
A27: datos.tables.limite_liquido.3.codigo | B27: D18 | C27: texto
A28: datos.tables.limite_liquido.3.golpes | B28: D19 | C28: numero | D28: 0
A29: datos.tables.limite_liquido.3.tara | B29: D20 | C29: numero | D29: 0.00
A30: datos.tables.limite_liquido.3.humedo | B30: D21 | C30: numero | D30: 0.00
A31: datos.tables.limite_liquido.3.seco | B31: D22 | C31: numero | D31: 0.00
A32: datos.tables.limite_plastico.1.codigo | B32: B31 | C32: texto
A33: datos.tables.limite_plastico.1.tara | B33: B32 | C33: numero | D33: 0.00
A34: datos.tables.limite_plastico.1.humedo | B34: B33 | C34: numero | D34: 0.00
A35: datos.tables.limite_plastico.1.seco | B35: B34 | C35: numero | D35: 0.00
A36: datos.tables.limite_plastico.2.codigo | B36: C31 | C36: texto
A37: datos.tables.limite_plastico.2.tara | B37: C32 | C37: numero | D37: 0.00
A38: datos.tables.limite_plastico.2.humedo | B38: C33 | C38: numero | D38: 0.00
A39: datos.tables.limite_plastico.2.seco | B39: C34 | C39: numero | D39: 0.00
A40: datos.tables.humedad_natural.1.codigo | B40: B48 | C40: texto
...
