Workbook
Name GranX: '_DATOS'!$A$3:$A$23
Name GranY: '_DATOS'!$B$3:$B$23

Sheet Reporte
C1: GOBIERNO REGIONAL CUSCO
C2: Gerencia Regional de Transportes y Comunicaciones Cusco
C3: SUB GERENCIA DE COBERTURA Y COMUNICACIONES
C4: UNIDAD FUNCIONAL ESTUDIOS Y PROYECTOS
C5: Laboratorio de Mecánica de Suelos, Materiales y Pavimentos
C6: «Año de la recuperación y consolidación de la economía peruana»
A8: CÓDIGO
A10: PROYECTO
A11: UBICACIÓN | B11: Lugar: | D11: Distrito: | F11: Provincia: | H11: Dpto:
A12: SOLICITANTE | E12: Fecha Muestreo:
A13: COORDENADAS | B13: E: | E13: N: | H13: Prof. (m):
A14: DATOS DE MUESTRA | B14: Explor.: | D14: Progresiva: | F14: Estrato: | H14: Lado:
A16: ANÁLISIS GRANULOMÉTRICO POR TAMIZADO - MTC E 107
A17: PESO TOTAL (g) | D17: PESO FRAC. FINA TAMIZADA (g)
A18: PESO FRACCIÓN GRUESA (g) | B18: =IF(N(B17)>0,SUM(C25:C34),"") | D18: PESO MUESTRA LAVADA (g) | F18: =IF(AND(N(B17)>0,N(F17)>0),B18+SUM(C35:C45)*B19/F17,"")
A19: PESO FRACCIÓN FINA (g) | B19: =IF(N(B17)>0,B17-B18,"") | D19: COEFICIENTE | F19: =IF(AND(N(B17)>0,N(F17)>0),IFERROR(F17/B17,0),"")
A20: LÍMITE LÍQUIDO (%) | D20: ÍNDICE DE PLASTICIDAD (%)
A21: GRADACIÓN
A23: TAMIZADO
A24: Tamiz | B24: mm | C24: Masa (g) | D24: % Ret Parcial | E24: % Ret Acum. | F24: % que Pasa
A25: 3" | B25: 75 | D25: =IF(AND(N(B17)>0,ISNUMBER(C25)),IFERROR(C25/B17*100,0),"") | E25: =IF(ISNUMBER(D25),D25,0) | F25: =100-E25
A26: 2 1/2" | B26: 62.9 | D26: =IF(AND(N(B17)>0,ISNUMBER(C26)),IFERROR(C26/B17*100,0),"") | E26: =IF(ISNUMBER(D26),E25+D26,E25) | F26: =100-E26
A27: 2" | B27: 50.8 | D27: =IF(AND(N(B17)>0,ISNUMBER(C27)),IFERROR(C27/B17*100,0),"") | E27: =IF(ISNUMBER(D27),E26+D27,E26) | F27: =100-E27
A28: 1 1/2" | B28: 38.1 | D28: =IF(AND(N(B17)>0,ISNUMBER(C28)),IFERROR(C28/B17*100,0),"") | E28: =IF(ISNUMBER(D28),E27+D28,E27) | F28: =100-E28
A29: 1" | B29: 25.4 | D29: =IF(AND(N(B17)>0,ISNUMBER(C29)),IFERROR(C29/B17*100,0),"") | E29: =IF(ISNUMBER(D29),E28+D29,E28) | F29: =100-E29
A30: 3/4" | B30: 19 | D30: =IF(AND(N(B17)>0,ISNUMBER(C30)),IFERROR(C30/B17*100,0),"") | E30: =IF(ISNUMBER(D30),E29+D30,E29) | F30: =100-E30
A31: 1/2" | B31: 12.7 | D31: =IF(AND(N(B17)>0,ISNUMBER(C31)),IFERROR(C31/B17*100,0),"") | E31: =IF(ISNUMBER(D31),E30+D31,E30) | F31: =100-E31
A32: 3/8" | B32: 9.5 | D32: =IF(AND(N(B17)>0,ISNUMBER(C32)),IFERROR(C32/B17*100,0),"") | E32: =IF(ISNUMBER(D32),E31+D32,E31) | F32: =100-E32
A33: 1/4" | B33: 6.3 | D33: =IF(AND(N(B17)>0,ISNUMBER(C33)),IFERROR(C33/B17*100,0),"") | E33: =IF(ISNUMBER(D33),E32+D33,E32) | F33: =100-E33
A34: N° 4 | B34: 4.76 | D34: =IF(AND(N(B17)>0,ISNUMBER(C34)),IFERROR(C34/B17*100,0),"") | E34: =IF(ISNUMBER(D34),E33+D34,E33) | F34: =100-E34
A35: N° 8 | B35: 2.36 | D35: =IF(AND(N(F17)>0,N(B17)>0,ISNUMBER(C35)),IFERROR(C35/F17*(B17-B18)/B17*100,0),"") | E35: =IF(ISNUMBER(D35),E34+D35,E34) | F35: =100-E35
A36: N° 10 | B36: 2 | D36: =IF(AND(N(F17)>0,N(B17)>0,ISNUMBER(C36)),IFERROR(C36/F17*(B17-B18)/B17*100,0),"") | E36: =IF(ISNUMBER(D36),E35+D36,E35) | F36: =100-E36
A37: N° 16 | B37: 1.1 | D37: =IF(AND(N(F17)>0,N(B17)>0,ISNUMBER(C37)),IFERROR(C37/F17*(B17-B18)/B17*100,0),"") | E37: =IF(ISNUMBER(D37),E36+D37,E36) | F37: =100-E37
A38: N° 20 | B38: 0.85 | D38: =IF(AND(N(F17)>0,N(B17)>0,ISNUMBER(C38)),IFERROR(C38/F17*(B17-B18)/B17*100,0),"") | E38: =IF(ISNUMBER(D38),E37+D38,E37) | F38: =100-E38
A39: N° 30 | B39: 0.59 | D39: =IF(AND(N(F17)>0,N(B17)>0,ISNUMBER(C39)),IFERROR(C39/F17*(B17-B18)/B17*100,0),"") | E39: =IF(ISNUMBER(D39),E38+D39,E38) | F39: =100-E39
A40: N° 40 | B40: 0.425 | D40: =IF(AND(N(F17)>0,N(B17)>0,ISNUMBER(C40)),IFERROR(C40/F17*(B17-B18)/B17*100,0),"") | E40: =IF(ISNUMBER(D40),E39+D40,E39) | F40: =100-E40
A41: N° 50 | B41: 0.297 | D41: =IF(AND(N(F17)>0,N(B17)>0,ISNUMBER(C41)),IFERROR(C41/F17*(B17-B18)/B17*100,0),"") | E41: =IF(ISNUMBER(D41),E40+D41,E40) | F41: =100-E41
A42: N° 60 | B42: 0.25 | D42: =IF(AND(N(F17)>0,N(B17)>0,ISNUMBER(C42)),IFERROR(C42/F17*(B17-B18)/B17*100,0),"") | E42: =IF(ISNUMBER(D42),E41+D42,E41) | F42: =100-E42
A43: N° 100 | B43: 0.149 | D43: =IF(AND(N(F17)>0,N(B17)>0,ISNUMBER(C43)),IFERROR(C43/F17*(B17-B18)/B17*100,0),"") | E43: =IF(ISNUMBER(D43),E42+D43,E42) | F43: =100-E43
A44: N° 140 | B44: 0.106 | D44: =IF(AND(N(F17)>0,N(B17)>0,ISNUMBER(C44)),IFERROR(C44/F17*(B17-B18)/B17*100,0),"") | E44: =IF(ISNUMBER(D44),E43+D44,E43) | F44: =100-E44
...

Sheet _DATOS
A3: 75 | B3: =IF(ISNUMBER(Reporte!F25),Reporte!F25,NA())
A4: 62.9 | B4: =IF(ISNUMBER(Reporte!F26),Reporte!F26,NA())
A5: 50.8 | B5: =IF(ISNUMBER(Reporte!F27),Reporte!F27,NA())
A6: 38.1 | B6: =IF(ISNUMBER(Reporte!F28),Reporte!F28,NA())
A7: 25.4 | B7: =IF(ISNUMBER(Reporte!F29),Reporte!F29,NA())
A8: 19 | B8: =IF(ISNUMBER(Reporte!F30),Reporte!F30,NA())
A9: 12.7 | B9: =IF(ISNUMBER(Reporte!F31),Reporte!F31,NA())
A10: 9.5 | B10: =IF(ISNUMBER(Reporte!F32),Reporte!F32,NA())
A11: 6.3 | B11: =IF(ISNUMBER(Reporte!F33),Reporte!F33,NA())
A12: 4.76 | B12: =IF(ISNUMBER(Reporte!F34),Reporte!F34,NA())
A13: 2.36 | B13: =IF(ISNUMBER(Reporte!F35),Reporte!F35,NA())
A14: 2 | B14: =IF(ISNUMBER(Reporte!F36),Reporte!F36,NA())
... A23: 0.075 | B23: =IF(ISNUMBER(Reporte!F45),Reporte!F45,NA())

Sheet _GRAFICOS
A1: id | B1: titulo | C1: tipo | D1: ancla | E1: ancho_px | F1: alto_px | G1: x_log | H1: x_min | I1: x_max | J1: y_min | K1: y_max | L1: titulo_x | M1: titulo_y | N1: serie | O1: estilo | P1: rango_x | Q1: rango_y | R1: color | S1: orden
A2: curva_granulometrica | B2: Curva Granulométrica | C2: xy | D2: A71 | E2: 620 | F2: 480 | G2: SI | H2: 0.01 | I2: 100 | J2: 0 | K2: 100 | L2: Abertura de Tamiz (mm) | M2: % que Pasa | N2: Curva Granulométrica | O2: linea_suave | P2: '_DATOS'!$A$3:$A$23 | Q2: '_DATOS'!$B$3:$B$23 | R2: 1E40AF | S2: 1
A3: curva_granulometrica | N3: Tamices | O3: marcador | P3: '_DATOS'!$A$3:$A$23 | Q3: '_DATOS'!$B$3:$B$23 | R3: 1E40AF | S3: 2

Sheet _MAPA
A1: ruta | B1: celda | C1: tipo | D1: formato
A2: meta.codigo_ensayo | B2: B8 | C2: texto
A3: meta.proyecto_nombre | B3: B10 | C3: texto
A4: meta.tramo_nombre | B4: C11 | C4: texto
A5: meta.distrito | B5: E11 | C5: texto
A6: meta.provincia | B6: G11 | C6: texto
A7: meta.departamento | B7: I11 | C7: texto
A8: meta.solicitante | B8: B12 | C8: texto
A9: meta.fecha_muestreo | B9: G12 | C9: fecha | D9: dddd d" de "mmmm" de "yyyy
A10: meta.coordenada_este | B10: C13 | C10: numero | D10: 0.00
A11: meta.coordenada_norte | B11: F13 | C11: numero | D11: 0.00
A12: meta.profundidad | B12: I13 | C12: texto
A13: meta.calicata | B13: C14 | C13: texto
A14: meta.progresiva | B14: E14 | C14: texto
A15: meta.estrato | B15: G14 | C15: texto
A16: meta.lado | B16: I14 | C16: texto
A17: datos.general_fields.peso_total | B17: B17 | C17: numero | D17: 0.00
A18: datos.general_fields.peso_fina_tamizada | B18: F17 | C18: numero | D18: 0.00
A19: datos.general_fields.limite_liquido | B19: B20 | C19: numero | D19: 0.00
A20: datos.general_fields.indice_plasticidad | B20: F20 | C20: numero | D20: 0.00
A21: datos.general_fields.gradacion | B21: B21 | C21: texto
A22: datos.tables.granulometria.malla_3p.retenido | B22: C25 | C22: numero | D22: 0.00
A23: datos.tables.granulometria.malla_2p5.retenido | B23: C26 | C23: numero | D23: 0.00
A24: datos.tables.granulometria.malla_2p.retenido | B24: C27 | C24: numero | D24: 0.00
A25: datos.tables.granulometria.malla_1p5.retenido | B25: C28 | C25: numero | D25: 0.00
A26: datos.tables.granulometria.malla_1p.retenido | B26: C29 | C26: numero | D26: 0.00
A27: datos.tables.granulometria.malla_3p4.retenido | B27: C30 | C27: numero | D27: 0.00
A28: datos.tables.granulometria.malla_1p2.retenido | B28: C31 | C28: numero | D28: 0.00
A29: datos.tables.granulometria.malla_3p8.retenido | B29: C32 | C29: numero | D29: 0.00
A30: datos.tables.granulometria.malla_1p4.retenido | B30: C33 | C30: numero | D30: 0.00
A31: datos.tables.granulometria.malla_04.retenido | B31: C34 | C31: numero | D31: 0.00
A32: datos.tables.granulometria.malla_08.retenido | B32: C35 | C32: numero | D32: 0.00
A33: datos.tables.granulometria.malla_10.retenido | B33: C36 | C33: numero | D33: 0.00
... A42: datos.tables.granulometria.malla_200.retenido | B42: C45 | C42: numero | D42: 0.00
